{"repository":"https://github.com/ethpm/ethpm-cli","dockerfilePath":"Dockerfile","startTime":1672485186534,"clone":{"stdout":"","stderr":"Cloning into '/tmp/dinghy-analysis/ethpm/ethpm-cli'...\n","error":null,"commit":"ea7097ad1a39fa703ec91e4751cdf9bc5ed1996b"},"originalBuild":{"startTimestamp":1672485187472,"endTimestamp":1672485193385,"error":{"code":1,"killed":false,"signal":null,"cmd":"docker build --no-cache --force-rm -t ethpm-cli:latest -f /tmp/dinghy-analysis/ethpm/ethpm-cli/Dockerfile ."},"stdout":"Sending build context to Docker daemon  746.5kB\r\r\nStep 1/7 : FROM python:3.7\n ---> 1f1a7b570f9e\nStep 2/7 : RUN mkdir -p /usr/src/app\n ---> Running in 5fcbcb7a3ff1\nRemoving intermediate container 5fcbcb7a3ff1\n ---> 2965111c049c\nStep 3/7 : WORKDIR /usr/src/app\n ---> Running in 47cee2f82db0\nRemoving intermediate container 47cee2f82db0\n ---> b3efcff2ab5d\nStep 4/7 : COPY . /usr/src/app\n ---> b76eb42dbe21\nStep 5/7 : RUN pip install -e .[dev]\n ---> Running in da9338f85fc7\nObtaining file:///usr/src/app\n  Preparing metadata (setup.py): started\n  Preparing metadata (setup.py): finished with status 'error'\n\u001b[91m  error: subprocess-exited-with-error\n  \n  × python setup.py egg_info did not run successfully.\n  │ exit code: 1\n  ╰─> [20 lines of output]\n      Traceback (most recent call last):\n        File \"<string>\", line 36, in <module>\n        File \"<pip-setuptools-caller>\", line 34, in <module>\n        File \"/usr/src/app/setup.py\", line 77, in <module>\n          'ethpm=ethpm_cli:main',\n        File \"/usr/local/lib/python3.7/site-packages/setuptools/__init__.py\", line 153, in setup\n          return distutils.core.setup(**attrs)\n        File \"/usr/local/lib/python3.7/distutils/core.py\", line 108, in setup\n          _setup_distribution = dist = klass(attrs)\n        File \"/usr/local/lib/python3.7/site-packages/setuptools/dist.py\", line 456, in __init__\n          k: v for k, v in attrs.items()\n        File \"/usr/local/lib/python3.7/distutils/dist.py\", line 292, in __init__\n          self.finalize_options()\n        File \"/usr/local/lib/python3.7/site-packages/setuptools/dist.py\", line 807, in finalize_options\n          ep(self)\n        File \"/usr/local/lib/python3.7/site-packages/setuptools/dist.py\", line 814, in _finalize_setup_keywords\n          ep.load()(self, ep.name, value)\n        File \"/usr/src/app/.eggs/setuptools_markdown-0.4.1-py3.7.egg/setuptools_markdown.py\", line 43, in long_description_markdown_filename\n          output = pypandoc.convert(markdown_filename, 'rst', format='md')\n      AttributeError: module 'pypandoc' has no attribute 'convert'\n      [end of output]\n  \n  note: This error originates from a subprocess, and is likely not a problem with pip.\n\u001b[0m\u001b[91merror: metadata-generation-failed\n\n× Encountered error while generating package metadata.\n╰─> See above for output.\n\nnote: This is an issue with the package mentioned above, not pip.\nhint: See above for details.\n\u001b[0m\u001b[91mWARNING: You are using pip version 22.0.4; however, version 22.3.1 is available.\nYou should consider upgrading via the '/usr/local/bin/python -m pip install --upgrade pip' command.\n\u001b[0mRemoving intermediate container da9338f85fc7\n","stderr":"The command '/bin/sh -c pip install -e .[dev]' returned a non-zero code: 1\n"},"endTime":1672485193445}